Workbook

Sheet VI-LP-1
A1: Week 1
A2: Introduction to RPi/Linux Operating System
A3: Annexure II
A4: Evaluation Rubrics
A5: Assessment Skill
A6: Roll No | B6: Name of the Student | C6: Discovery | H6: Understanding/ Problem Solving | M6: Completion of Tasks | R6: Interest/Motivation | W6: Team Work | AB6: LP-1
C7: Beginner (25%) | D7: Needs Improvement (50%) | E7: Comfortable (75%) | F7: Skilled (100%) | H7: Beginner (25%) | I7: Needs Improvement (50%) | J7: Comfortable (75%) | K7: Skilled (100%) | M7: Beginner (25%) | N7: Needs Improvement (50%) | O7: Comfortable (75%) | P7: Skilled (100%) | R7: Beginner (25%) | S7: Needs Improvement (50%) | T7: Comfortable (75%) | U7: Skilled (100%) | W7: Beginner (25%) | X7: Needs Improvement (50%) | Y7: Comfortable (75%) | Z7: Skilled (100%)
C8: The student can identify some of the components of a computer | D8: The student can identify all the components of a computer but needs help in understanding their/its purpose | E8: The student can identify some of the components of a computer and explain at least half of them | F8: The studentt can identify and explains the purpose of all the components of a computer | H8: The student can identify how to start, but not shut down, or open programs. | I8: The student can identify few steps to start/ shut down the computer but needs help in understanding how to open programs. | J8: The student can identify how to start, shutdown, open programs but needs help to open CLI. | K8: The student can start, shutdown, and open any programs on the computer using CLI /GUI. | M8: The student finds it challenging to complete a task. | N8: The student attempts the task but completes a minor portion of the task assigned. | O8: The student attempts the task and completes most of it. | P8: The student attempts the task and completes the entire task confidently. | R8: The student shows a lack of interest in the session | S8: The student is keen on learning the GUI however fears completing the task on his/her own. | T8: The student shows interest in the completion of the assigned task, however, is less motivated to explore independently. | U8: The student is confident and motivated to explore applications independently. | W8: The student was a passive member of the team. | X8: The student was considering all the opinions of the peer team members . | Y8: The student was able to filter and go ahead with the right opinion provided by the teammates. | Z8: The student completed his/her work and also helped other team members by solving their difficulties wherever possible.
C9: 2 | D9: 3 | E9: 4 | F9: 5 | G9: Total/5 | H9: 2 | I9: 3 | J9: 4 | K9: 5 | L9: Total/5 | M9: 2 | N9: 3 | O9: 4 | P9: 5 | Q9: Total/5 | R9: 2 | S9: 3 | T9: 4 | U9: 5 | V9: Total/5 | W9: 2 | X9: 3 | Y9: 4 | Z9: 5 | AA9: Total/5 | AB9: Grand Total/25 | AC9: Grade
A10: 1 | C10: 0 | D10: 0 | E10: 0 | F10: 0 | G10: =SUM(C10:F10) -> 0 | H10: 0 | I10: 0 | J10: 0 | K10: 0 | L10: =SUM(H10:K10) -> 0 | M10: 0 | N10: 0 | O10: 0 | P10: 0 | Q10: =SUM(M10:P10) -> 0 | R10: 0 | S10: 0 | T10: 0 | U10: 0 | V10: =SUM(R10:U10) -> 0 | W10: 0 | X10: 0 | Y10: 0 | Z10: 0 | AA10: =SUM(W10:Z10) -> 0 | AB10: =G10+L10+Q10+AA10+AA10 -> 0 | AC10: =IF(AB10>=20,"A",IF(AB10>=15,"B",IF(AB10>=10,"C","D"))) -> D
A11: 2 | C11: 0 | D11: 0 | E11: 0 | F11: 0 | G11: =SUM(C11:F11) -> 0 | H11: 0 | I11: 0 | J11: 0 | K11: 0 | L11: =SUM(H11:K11) -> 0 | M11: 0 | N11: 0 | O11: 0 | P11: 0 | Q11: =SUM(M11:P11) -> 0 | R11: 0 | S11: 0 | T11: 0 | U11: 0 | V11: =SUM(R11:U11) -> 0 | W11: 0 | X11: 0 | Y11: 0 | Z11: 0 | AA11: =SUM(W11:Z11) -> 0 | AB11: =G11+L11+Q11+AA11+AA11 -> 0 | AC11: =IF(AB11>=20,"A",IF(AB11>=15,"B",IF(AB11>=10,"C","D"))) -> D
A12: 3 | C12: 0 | D12: 0 | E12: 0 | F12: 0 | G12: =SUM(C12:F12) -> 0 | H12: 0 | I12: 0 | J12: 0 | K12: 0 | L12: =SUM(H12:K12) -> 0 | M12: 0 | N12: 0 | O12: 0 | P12: 0 | Q12: =SUM(M12:P12) -> 0 | R12: 0 | S12: 0 | T12: 0 | U12: 0 | V12: =SUM(R12:U12) -> 0 | W12: 0 | X12: 0 | Y12: 0 | Z12: 0 | AA12: =SUM(W12:Z12) -> 0 | AB12: =G12+L12+Q12+AA12+AA12 -> 0 | AC12: =IF(AB12>=20,"A",IF(AB12>=15,"B",IF(AB12>=10,"C","D"))) -> D
A13: 4 | C13: 0 | D13: 0 | E13: 0 | F13: 0 | G13: =SUM(C13:F13) -> 0 | H13: 0 | I13: 0 | J13: 0 | K13: 0 | L13: =SUM(H13:K13) -> 0 | M13: 0 | N13: 0 | O13: 0 | P13: 0 | Q13: =SUM(M13:P13) -> 0 | R13: 0 | S13: 0 | T13: 0 | U13: 0 | V13: =SUM(R13:U13) -> 0 | W13: 0 | X13: 0 | Y13: 0 | Z13: 0 | AA13: =SUM(W13:Z13) -> 0 | AB13: =G13+L13+Q13+AA13+AA13 -> 0 | AC13: =IF(AB13>=20,"A",IF(AB13>=15,"B",IF(AB13>=10,"C","D"))) -> D
A14: 5 | C14: 0 | D14: 0 | E14: 0 | F14: 0 | G14: =SUM(C14:F14) -> 0 | H14: 0 | I14: 0 | J14: 0 | K14: 0 | L14: =SUM(H14:K14) -> 0 | M14: 0 | N14: 0 | O14: 0 | P14: 0 | Q14: =SUM(M14:P14) -> 0 | R14: 0 | S14: 0 | T14: 0 | U14: 0 | V14: =SUM(R14:U14) -> 0 | W14: 0 | X14: 0 | Y14: 0 | Z14: 0 | AA14: =SUM(W14:Z14) -> 0 | AB14: =G14+L14+Q14+AA14+AA14 -> 0 | AC14: =IF(AB14>=20,"A",IF(AB14>=15,"B",IF(AB14>=10,"C","D"))) -> D
A15: 6 | C15: 0 | D15: 0 | E15: 0 | F15: 0 | G15: =SUM(C15:F15) -> 0 | H15: 0 | I15: 0 | J15: 0 | K15: 0 | L15: =SUM(H15:K15) -> 0 | M15: 0 | N15: 0 | O15: 0 | P15: 0 | Q15: =SUM(M15:P15) -> 0 | R15: 0 | S15: 0 | T15: 0 | U15: 0 | V15: =SUM(R15:U15) -> 0 | W15: 0 | X15: 0 | Y15: 0 | Z15: 0 | AA15: =SUM(W15:Z15) -> 0 | AB15: =G15+L15+Q15+AA15+AA15 -> 0 | AC15: =IF(AB15>=20,"A",IF(AB15>=15,"B",IF(AB15>=10,"C","D"))) -> D
A16: 7 | C16: 0 | D16: 0 | E16: 0 | F16: 0 | G16: =SUM(C16:F16) -> 0 | H16: 0 | I16: 0 | J16: 0 | K16: 0 | L16: =SUM(H16:K16) -> 0 | M16: 0 | N16: 0 | O16: 0 | P16: 0 | Q16: =SUM(M16:P16) -> 0 | R16: 0 | S16: 0 | T16: 0 | U16: 0 | V16: =SUM(R16:U16) -> 0 | W16: 0 | X16: 0 | Y16: 0 | Z16: 0 | AA16: =SUM(W16:Z16) -> 0 | AB16: =G16+L16+Q16+AA16+AA16 -> 0 | AC16: =IF(AB16>=20,"A",IF(AB16>=15,"B",IF(AB16>=10,"C","D"))) -> D
A17: 8 | C17: 0 | D17: 0 | E17: 0 | F17: 0 | G17: =SUM(C17:F17) -> 0 | H17: 0 | I17: 0 | J17: 0 | K17: 0 | L17: =SUM(H17:K17) -> 0 | M17: 0 | N17: 0 | O17: 0 | P17: 0 | Q17: =SUM(M17:P17) -> 0 | R17: 0 | S17: 0 | T17: 0 | U17: 0 | V17: =SUM(R17:U17) -> 0 | W17: 0 | X17: 0 | Y17: 0 | Z17: 0 | AA17: =SUM(W17:Z17) -> 0 | AB17: =G17+L17+Q17+AA17+AA17 -> 0 | AC17: =IF(AB17>=20,"A",IF(AB17>=15,"B",IF(AB17>=10,"C","D"))) -> D
A18: 9 | C18: 0 | D18: 0 | E18: 0 | F18: 0 | G18: =SUM(C18:F18) -> 0 | H18: 0 | I18: 0 | J18: 0 | K18: 0 | L18: =SUM(H18:K18) -> 0 | M18: 0 | N18: 0 | O18: 0 | P18: 0 | Q18: =SUM(M18:P18) -> 0 | R18: 0 | S18: 0 | T18: 0 | U18: 0 | V18: =SUM(R18:U18) -> 0 | W18: 0 | X18: 0 | Y18: 0 | Z18: 0 | AA18: =SUM(W18:Z18) -> 0 | AB18: =G18+L18+Q18+AA18+AA18 -> 0 | AC18: =IF(AB18>=20,"A",IF(AB18>=15,"B",IF(AB18>=10,"C","D"))) -> D
A19: 10 | C19: 0 | D19: 0 | E19: 0 | F19: 0 | G19: =SUM(C19:F19) -> 0 | H19: 0 | I19: 0 | J19: 0 | K19: 0 | L19: =SUM(H19:K19) -> 0 | M19: 0 | N19: 0 | O19: 0 | P19: 0 | Q19: =SUM(M19:P19) -> 0 | R19: 0 | S19: 0 | T19: 0 | U19: 0 | V19: =SUM(R19:U19) -> 0 | W19: 0 | X19: 0 | Y19: 0 | Z19: 0 | AA19: =SUM(W19:Z19) -> 0 | AB19: =G19+L19+Q19+AA19+AA19 -> 0 | AC19: =IF(AB19>=20,"A",IF(AB19>=15,"B",IF(AB19>=10,"C","D"))) -> D
A20: 11 | C20: 0 | D20: 0 | E20: 0 | F20: 0 | G20: =SUM(C20:F20) -> 0 | H20: 0 | I20: 0 | J20: 0 | K20: 0 | L20: =SUM(H20:K20) -> 0 | M20: 0 | N20: 0 | O20: 0 | P20: 0 | Q20: =SUM(M20:P20) -> 0 | R20: 0 | S20: 0 | T20: 0 | U20: 0 | V20: =SUM(R20:U20) -> 0 | W20: 0 | X20: 0 | Y20: 0 | Z20: 0 | AA20: =SUM(W20:Z20) -> 0 | AB20: =G20+L20+Q20+AA20+AA20 -> 0 | AC20: =IF(AB20>=20,"A",IF(AB20>=15,"B",IF(AB20>=10,"C","D"))) -> D
A21: 12 | C21: 0 | D21: 0 | E21: 0 | F21: 0 | G21: =SUM(C21:F21) -> 0 | H21: 0 | I21: 0 | J21: 0 | K21: 0 | L21: =SUM(H21:K21) -> 0 | M21: 0 | N21: 0 | O21: 0 | P21: 0 | Q21: =SUM(M21:P21) -> 0 | R21: 0 | S21: 0 | T21: 0 | U21: 0 | V21: =SUM(R21:U21) -> 0 | W21: 0 | X21: 0 | Y21: 0 | Z21: 0 | AA21: =SUM(W21:Z21) -> 0 | AB21: =G21+L21+Q21+AA21+AA21 -> 0 | AC21: =IF(AB21>=20,"A",IF(AB21>=15,"B",IF(AB21>=10,"C","D"))) -> D
... A59: 50 | C59: 0 | D59: 0 | E59: 0 | F59: 0 | G59: =SUM(C59:F59) -> 0 | H59: 0 | I59: 0 | J59: 0 | K59: 0 | L59: =SUM(H59:K59) -> 0 | M59: 0 | N59: 0 | O59: 0 | P59: 0 | Q59: =SUM(M59:P59) -> 0 | R59: 0 | S59: 0 | T59: 0 | U59: 0 | V59: =SUM(R59:U59) -> 0 | W59: 0 | X59: 0 | Y59: 0 | Z59: 0 | AA59: =SUM(W59:Z59) -> 0 | AB59: =G59+L59+Q59+AA59+AA59 -> 0 | AC59: =IF(AB59>=20,"A",IF(AB59>=15,"B",IF(AB59>=10,"C","D"))) -> D

Sheet VI-LP-2
A1: Week 2
A2: Introduction to RPi/Linux Operating System (Command Line Tour)
A3: Annexure II
A4: Evaluation Rubrics
A5: Assessment Skill
A6: Roll No | B6: Name of the Student | C6: Discovery | H6: Understanding/ Problem Solving | M6: Completion of Tasks | R6: Interest/Motivation | W6: Team Work | AB6: LP-2
C7: Beginner (25%) | D7: Needs Improvement (50%) | E7: Comfortable (75%) | F7: Skilled (100%) | H7: Beginner (25%) | I7: Needs Improvement (50%) | J7: Comfortable (75%) | K7: Skilled (100%) | M7: Beginner (25%) | N7: Needs Improvement (50%) | O7: Comfortable (75%) | P7: Skilled (100%) | R7: Beginner (25%) | S7: Needs Improvement (50%) | T7: Comfortable (75%) | U7: Skilled (100%) | W7: Beginner (25%) | X7: Needs Improvement (50%) | Y7: Comfortable (75%) | Z7: Skilled (100%)
C8: It was challenging for the student to write the correct syntax for commands and execute the commands. | D8: The student was able to write the syntax for few commands . | E8: The student was able to write the syntax for some of the commands and execute them too. | F8: The student was not only able to write the syntax for all the given commands but also explored new commands in Linux. | H8: The student found it a challenge to understand the working of the commands. | I8: The student partially understood the working of a few commands | J8: The student could understand and partially explain the commands. | K8: The student was quick to understand the commands and could explain the same with clarity. | M8: The student could not execute any command. | N8: The student could execute some of the commands. | O8: The student could execute all the commands. | P8: The student could execute these commands and tried some new. | R8: The student showed very little interest in the activity. | S8: The student displayed/ showed a fair interest in the activity. | T8: The student participated in the activity with interest. | U8: The student was excited about performing the activity. | W8: The student was a passive member of the team. | X8: The student was considering all the opinions of the peer team members . | Y8: The student was able to filter and go ahead with the right opinion provided by the teammates. | Z8: The student completed his/her work and also helped other team members by solving their difficulties wherever possible.
C9: 2 | D9: 3 | E9: 4 | F9: 5 | G9: Total/5 | H9: 2 | I9: 3 | J9: 4 | K9: 5 | L9: Total/5 | M9: 2 | N9: 3 | O9: 4 | P9: 5 | Q9: Total/5 | R9: 2 | S9: 3 | T9: 4 | U9: 5 | V9: Total/5 | W9: 2 | X9: 3 | Y9: 4 | Z9: 5 | AA9: Total/5 | AB9: Grand Total/25 | AC9: Grade
A10: 1 | C10: 2 | D10: 0 | E10: 0 | F10: 0 | G10: =SUM(C10:F10) -> 2 | H10: 0 | I10: 0 | J10: 0 | K10: 0 | L10: =SUM(H10:K10) -> 0 | M10: 0 | N10: 0 | O10: 0 | P10: 0 | Q10: =SUM(M10:P10) -> 0 | R10: 0 | S10: 0 | T10: 0 | U10: 0 | V10: =SUM(R10:U10) -> 0 | W10: 0 | X10: 0 | Y10: 0 | Z10: 0 | AA10: =SUM(W10:Z10) -> 0 | AB10: =G10+L10+Q10+AA10+AA10 -> 2 | AC10: =IF(AB10>=20,"A",IF(AB10>=15,"B",IF(AB10>=10,"C","D"))) -> D
A11: 2 | C11: 0 | D11: 0 | E11: 0 | F11: 0 | G11: =SUM(C11:F11) -> 0 | H11: 0 | I11: 0 | J11: 0 | K11: 0 | L11: =SUM(H11:K11) -> 0 | M11: 0 | N11: 0 | O11: 0 | P11: 0 | Q11: =SUM(M11:P11) -> 0 | R11: 0 | S11: 0 | T11: 0 | U11: 0 | V11: =SUM(R11:U11) -> 0 | W11: 0 | X11: 0 | Y11: 0 | Z11: 0 | AA11: =SUM(W11:Z11) -> 0 | AB11: =G11+L11+Q11+AA11+AA11 -> 0 | AC11: =IF(AB11>=20,"A",IF(AB11>=15,"B",IF(AB11>=10,"C","D"))) -> D
A12: 3 | C12: 0 | D12: 0 | E12: 0 | F12: 0 | G12: =SUM(C12:F12) -> 0 | H12: 0 | I12: 0 | J12: 0 | K12: 0 | L12: =SUM(H12:K12) -> 0 | M12: 0 | N12: 0 | O12: 0 | P12: 0 | Q12: =SUM(M12:P12) -> 0 | R12: 0 | S12: 0 | T12: 0 | U12: 0 | V12: =SUM(R12:U12) -> 0 | W12: 0 | X12: 0 | Y12: 0 | Z12: 0 | AA12: =SUM(W12:Z12) -> 0 | AB12: =G12+L12+Q12+AA12+AA12 -> 0 | AC12: =IF(AB12>=20,"A",IF(AB12>=15,"B",IF(AB12>=10,"C","D"))) -> D
A13: 4 | C13: 0 | D13: 0 | E13: 0 | F13: 0 | G13: =SUM(C13:F13) -> 0 | H13: 0 | I13: 0 | J13: 0 | K13: 0 | L13: =SUM(H13:K13) -> 0 | M13: 0 | N13: 0 | O13: 0 | P13: 0 | Q13: =SUM(M13:P13) -> 0 | R13: 0 | S13: 0 | T13: 0 | U13: 0 | V13: =SUM(R13:U13) -> 0 | W13: 0 | X13: 0 | Y13: 0 | Z13: 0 | AA13: =SUM(W13:Z13) -> 0 | AB13: =G13+L13+Q13+AA13+AA13 -> 0 | AC13: =IF(AB13>=20,"A",IF(AB13>=15,"B",IF(AB13>=10,"C","D"))) -> D
A14: 5 | C14: 0 | D14: 0 | E14: 0 | F14: 0 | G14: =SUM(C14:F14) -> 0 | H14: 0 | I14: 0 | J14: 0 | K14: 0 | L14: =SUM(H14:K14) -> 0 | M14: 0 | N14: 0 | O14: 0 | P14: 0 | Q14: =SUM(M14:P14) -> 0 | R14: 0 | S14: 0 | T14: 0 | U14: 0 | V14: =SUM(R14:U14) -> 0 | W14: 0 | X14: 0 | Y14: 0 | Z14: 0 | AA14: =SUM(W14:Z14) -> 0 | AB14: =G14+L14+Q14+AA14+AA14 -> 0 | AC14: =IF(AB14>=20,"A",IF(AB14>=15,"B",IF(AB14>=10,"C","D"))) -> D
A15: 6 | C15: 0 | D15: 0 | E15: 0 | F15: 0 | G15: =SUM(C15:F15) -> 0 | H15: 0 | I15: 0 | J15: 0 | K15: 0 | L15: =SUM(H15:K15) -> 0 | M15: 0 | N15: 0 | O15: 0 | P15: 0 | Q15: =SUM(M15:P15) -> 0 | R15: 0 | S15: 0 | T15: 0 | U15: 0 | V15: =SUM(R15:U15) -> 0 | W15: 0 | X15: 0 | Y15: 0 | Z15: 0 | AA15: =SUM(W15:Z15) -> 0 | AB15: =G15+L15+Q15+AA15+AA15 -> 0 | AC15: =IF(AB15>=20,"A",IF(AB15>=15,"B",IF(AB15>=10,"C","D"))) -> D
A16: 7 | C16: 0 | D16: 0 | E16: 0 | F16: 0 | G16: =SUM(C16:F16) -> 0 | H16: 0 | I16: 0 | J16: 0 | K16: 0 | L16: =SUM(H16:K16) -> 0 | M16: 0 | N16: 0 | O16: 0 | P16: 0 | Q16: =SUM(M16:P16) -> 0 | R16: 0 | S16: 0 | T16: 0 | U16: 0 | V16: =SUM(R16:U16) -> 0 | W16: 0 | X16: 0 | Y16: 0 | Z16: 0 | AA16: =SUM(W16:Z16) -> 0 | AB16: =G16+L16+Q16+AA16+AA16 -> 0 | AC16: =IF(AB16>=20,"A",IF(AB16>=15,"B",IF(AB16>=10,"C","D"))) -> D
A17: 8 | C17: 0 | D17: 0 | E17: 0 | F17: 0 | G17: =SUM(C17:F17) -> 0 | H17: 0 | I17: 0 | J17: 0 | K17: 0 | L17: =SUM(H17:K17) -> 0 | M17: 0 | N17: 0 | O17: 0 | P17: 0 | Q17: =SUM(M17:P17) -> 0 | R17: 0 | S17: 0 | T17: 0 | U17: 0 | V17: =SUM(R17:U17) -> 0 | W17: 0 | X17: 0 | Y17: 0 | Z17: 0 | AA17: =SUM(W17:Z17) -> 0 | AB17: =G17+L17+Q17+AA17+AA17 -> 0 | AC17: =IF(AB17>=20,"A",IF(AB17>=15,"B",IF(AB17>=10,"C","D"))) -> D
A18: 9 | C18: 0 | D18: 0 | E18: 0 | F18: 0 | G18: =SUM(C18:F18) -> 0 | H18: 0 | I18: 0 | J18: 0 | K18: 0 | L18: =SUM(H18:K18) -> 0 | M18: 0 | N18: 0 | O18: 0 | P18: 0 | Q18: =SUM(M18:P18) -> 0 | R18: 0 | S18: 0 | T18: 0 | U18: 0 | V18: =SUM(R18:U18) -> 0 | W18: 0 | X18: 0 | Y18: 0 | Z18: 0 | AA18: =SUM(W18:Z18) -> 0 | AB18: =G18+L18+Q18+AA18+AA18 -> 0 | AC18: =IF(AB18>=20,"A",IF(AB18>=15,"B",IF(AB18>=10,"C","D"))) -> D
A19: 10 | C19: 0 | D19: 0 | E19: 0 | F19: 0 | G19: =SUM(C19:F19) -> 0 | H19: 0 | I19: 0 | J19: 0 | K19: 0 | L19: =SUM(H19:K19) -> 0 | M19: 0 | N19: 0 | O19: 0 | P19: 0 | Q19: =SUM(M19:P19) -> 0 | R19: 0 | S19: 0 | T19: 0 | U19: 0 | V19: =SUM(R19:U19) -> 0 | W19: 0 | X19: 0 | Y19: 0 | Z19: 0 | AA19: =SUM(W19:Z19) -> 0 | AB19: =G19+L19+Q19+AA19+AA19 -> 0 | AC19: =IF(AB19>=20,"A",IF(AB19>=15,"B",IF(AB19>=10,"C","D"))) -> D
A20: 11 | C20: 0 | D20: 0 | E20: 0 | F20: 0 | G20: =SUM(C20:F20) -> 0 | H20: 0 | I20: 0 | J20: 0 | K20: 0 | L20: =SUM(H20:K20) -> 0 | M20: 0 | N20: 0 | O20: 0 | P20: 0 | Q20: =SUM(M20:P20) -> 0 | R20: 0 | S20: 0 | T20: 0 | U20: 0 | V20: =SUM(R20:U20) -> 0 | W20: 0 | X20: 0 | Y20: 0 | Z20: 0 | AA20: =SUM(W20:Z20) -> 0 | AB20: =G20+L20+Q20+AA20+AA20 -> 0 | AC20: =IF(AB20>=20,"A",IF(AB20>=15,"B",IF(AB20>=10,"C","D"))) -> D
A21: 12 | C21: 0 | D21: 0 | E21: 0 | F21: 0 | G21: =SUM(C21:F21) -> 0 | H21: 0 | I21: 0 | J21: 0 | K21: 0 | L21: =SUM(H21:K21) -> 0 | M21: 0 | N21: 0 | O21: 0 | P21: 0 | Q21: =SUM(M21:P21) -> 0 | R21: 0 | S21: 0 | T21: 0 | U21: 0 | V21: =SUM(R21:U21) -> 0 | W21: 0 | X21: 0 | Y21: 0 | Z21: 0 | AA21: =SUM(W21:Z21) -> 0 | AB21: =G21+L21+Q21+AA21+AA21 -> 0 | AC21: =IF(AB21>=20,"A",IF(AB21>=15,"B",IF(AB21>=10,"C","D"))) -> D
... A59: 50 | C59: 0 | D59: 0 | E59: 0 | F59: 0 | G59: =SUM(C59:F59) -> 0 | H59: 0 | I59: 0 | J59: 0 | K59: 0 | L59: =SUM(H59:K59) -> 0 | M59: 0 | N59: 0 | O59: 0 | P59: 0 | Q59: =SUM(M59:P59) -> 0 | R59: 0 | S59: 0 | T59: 0 | U59: 0 | V59: =SUM(R59:U59) -> 0 | W59: 0 | X59: 0 | Y59: 0 | Z59: 0 | AA59: =SUM(W59:Z59) -> 0 | AB59: =G59+L59+Q59+AA59+AA59 -> 0 | AC59: =IF(AB59>=20,"A",IF(AB59>=15,"B",IF(AB59>=10,"C","D"))) -> D

Sheet VI-LP-3
A1: Week 3
A2: Fun with Cat Sprite - Bouncing Cat
A3: Annexure II
A4: Evaluation Rubrics
A5: Assessment Skill
A6: Roll No | B6: Name of the Student | C6: Discovery | H6: Understanding/ Problem | M6: Completion of Tasks | R6: Interest/Motivation | W6: Team Work | AB6: LP-3
C7: Beginner (25%) | D7: Needs Improvement (50%) | E7: Comfortable (75%) | F7: Skilled (100%) | H7: Beginner (25%) | I7: Needs Improvement (50%) | J7: Comfortable (75%) | K7: Skilled (100%) | M7: Beginner (25%) | N7: Needs Improvement (50%) | O7: Comfortable (75%) | P7: Skilled (100%) | R7: Beginner (25%) | S7: Needs Improvement (50%) | T7: Comfortable (75%) | U7: Skilled (100%) | W7: Beginner (25%) | X7: Needs Improvement (50%) | Y7: Comfortable (75%) | Z7: Skilled (100%)
C8: It was a challenge for the student to find the appropriate blocks in the palette. | D8: The student was able to find some blocks, however required help for discovering the others. | E8: The student found all the required blocks without any difficulty. | F8: The student was not only able to discover all the blocks in the palette but also explored other blocks in the palette. | H8: The student found it a challenge to understand the task | I8: The student partially understood the task. | J8: The student could understand and explain the task partially. | K8: The student was quick to understand the task and could explain the same with clarity. | M8: The student could not get a solution within the given time. | N8: The student struggled to get a solution for the first task. | O8: The student got a solution for the first task but struggled a bit with further tasks. | P8: The student could get the solution for most of the tasks easily and also tried some tasks of his/her own. | R8: The student showed very little interest in the activity. | S8: The student displayed a fair bit of interest in the activity. | T8: The student participated in the activity with interest. | U8: The student was excited about performing the activity. | W8: The student was a passive member of the team. | X8: The student was considering all the opinions of the peer team members . | Y8: The student was able to filter and go ahead with the right opinion provided by the teammates. | Z8: The student completed his/her work and also helped other team members by solving their difficulties wherever possible.
C9: 2 | D9: 3 | E9: 4 | F9: 5 | G9: Total/5 | H9: 2 | I9: 3 | J9: 4 | K9: 5 | L9: Total/5 | M9: 2 | N9: 3 | O9: 4 | P9: 5 | Q9: Total/5 | R9: 2 | S9: 3 | T9: 4 | U9: 5 | V9: Total/5 | W9: 2 | X9: 3 | Y9: 4 | Z9: 5 | AA9: Total/5 | AB9: Grand Total/25 | AC9: Grade
A10: 1 | C10: 0 | D10: 0 | E10: 0 | F10: 5 | G10: =SUM(C10:F10) -> 5 | H10: 0 | I10: 0 | J10: 0 | K10: 0 | L10: =SUM(H10:K10) -> 0 | M10: 0 | N10: 0 | O10: 0 | P10: 0 | Q10: =SUM(M10:P10) -> 0 | R10: 0 | S10: 0 | T10: 0 | U10: 0 | V10: =SUM(R10:U10) -> 0 | W10: 0 | X10: 0 | Y10: 0 | Z10: 0 | AA10: =SUM(W10:Z10) -> 0 | AB10: =G10+L10+Q10+AA10+AA10 -> 5 | AC10: =IF(AB10>=20,"A",IF(AB10>=15,"B",IF(AB10>=10,"C","D"))) -> D
A11: 2 | C11: 0 | D11: 0 | E11: 0 | F11: 0 | G11: =SUM(C11:F11) -> 0 | H11: 0 | I11: 0 | J11: 0 | K11: 0 | L11: =SUM(H11:K11) -> 0 | M11: 0 | N11: 0 | O11: 0 | P11: 0 | Q11: =SUM(M11:P11) -> 0 | R11: 0 | S11: 0 | T11: 0 | U11: 0 | V11: =SUM(R11:U11) -> 0 | W11: 0 | X11: 0 | Y11: 0 | Z11: 0 | AA11: =SUM(W11:Z11) -> 0 | AB11: =G11+L11+Q11+AA11+AA11 -> 0 | AC11: =IF(AB11>=20,"A",IF(AB11>=15,"B",IF(AB11>=10,"C","D"))) -> D
A12: 3 | C12: 0 | D12: 0 | E12: 0 | F12: 0 | G12: =SUM(C12:F12) -> 0 | H12: 0 | I12: 0 | J12: 0 | K12: 0 | L12: =SUM(H12:K12) -> 0 | M12: 0 | N12: 0 | O12: 0 | P12: 0 | Q12: =SUM(M12:P12) -> 0 | R12: 0 | S12: 0 | T12: 0 | U12: 0 | V12: =SUM(R12:U12) -> 0 | W12: 0 | X12: 0 | Y12: 0 | Z12: 0 | AA12: =SUM(W12:Z12) -> 0 | AB12: =G12+L12+Q12+AA12+AA12 -> 0 | AC12: =IF(AB12>=20,"A",IF(AB12>=15,"B",IF(AB12>=10,"C","D"))) -> D
A13: 4 | C13: 0 | D13: 0 | E13: 0 | F13: 0 | G13: =SUM(C13:F13) -> 0 | H13: 0 | I13: 0 | J13: 0 | K13: 0 | L13: =SUM(H13:K13) -> 0 | M13: 0 | N13: 0 | O13: 0 | P13: 0 | Q13: =SUM(M13:P13) -> 0 | R13: 0 | S13: 0 | T13: 0 | U13: 0 | V13: =SUM(R13:U13) -> 0 | W13: 0 | X13: 0 | Y13: 0 | Z13: 0 | AA13: =SUM(W13:Z13) -> 0 | AB13: =G13+L13+Q13+AA13+AA13 -> 0 | AC13: =IF(AB13>=20,"A",IF(AB13>=15,"B",IF(AB13>=10,"C","D"))) -> D
A14: 5 | C14: 0 | D14: 0 | E14: 0 | F14: 0 | G14: =SUM(C14:F14) -> 0 | H14: 0 | I14: 0 | J14: 0 | K14: 0 | L14: =SUM(H14:K14) -> 0 | M14: 0 | N14: 0 | O14: 0 | P14: 0 | Q14: =SUM(M14:P14) -> 0 | R14: 0 | S14: 0 | T14: 0 | U14: 0 | V14: =SUM(R14:U14) -> 0 | W14: 0 | X14: 0 | Y14: 0 | Z14: 0 | AA14: =SUM(W14:Z14) -> 0 | AB14: =G14+L14+Q14+AA14+AA14 -> 0 | AC14: =IF(AB14>=20,"A",IF(AB14>=15,"B",IF(AB14>=10,"C","D"))) -> D
A15: 6 | C15: 0 | D15: 0 | E15: 0 | F15: 0 | G15: =SUM(C15:F15) -> 0 | H15: 0 | I15: 0 | J15: 0 | K15: 0 | L15: =SUM(H15:K15) -> 0 | M15: 0 | N15: 0 | O15: 0 | P15: 0 | Q15: =SUM(M15:P15) -> 0 | R15: 0 | S15: 0 | T15: 0 | U15: 0 | V15: =SUM(R15:U15) -> 0 | W15: 0 | X15: 0 | Y15: 0 | Z15: 0 | AA15: =SUM(W15:Z15) -> 0 | AB15: =G15+L15+Q15+AA15+AA15 -> 0 | AC15: =IF(AB15>=20,"A",IF(AB15>=15,"B",IF(AB15>=10,"C","D"))) -> D
A16: 7 | C16: 0 | D16: 0 | E16: 0 | F16: 0 | G16: =SUM(C16:F16) -> 0 | H16: 0 | I16: 0 | J16: 0 | K16: 0 | L16: =SUM(H16:K16) -> 0 | M16: 0 | N16: 0 | O16: 0 | P16: 0 | Q16: =SUM(M16:P16) -> 0 | R16: 0 | S16: 0 | T16: 0 | U16: 0 | V16: =SUM(R16:U16) -> 0 | W16: 0 | X16: 0 | Y16: 0 | Z16: 0 | AA16: =SUM(W16:Z16) -> 0 | AB16: =G16+L16+Q16+AA16+AA16 -> 0 | AC16: =IF(AB16>=20,"A",IF(AB16>=15,"B",IF(AB16>=10,"C","D"))) -> D
A17: 8 | C17: 0 | D17: 0 | E17: 0 | F17: 0 | G17: =SUM(C17:F17) -> 0 | H17: 0 | I17: 0 | J17: 0 | K17: 0 | L17: =SUM(H17:K17) -> 0 | M17: 0 | N17: 0 | O17: 0 | P17: 0 | Q17: =SUM(M17:P17) -> 0 | R17: 0 | S17: 0 | T17: 0 | U17: 0 | V17: =SUM(R17:U17) -> 0 | W17: 0 | X17: 0 | Y17: 0 | Z17: 0 | AA17: =SUM(W17:Z17) -> 0 | AB17: =G17+L17+Q17+AA17+AA17 -> 0 | AC17: =IF(AB17>=20,"A",IF(AB17>=15,"B",IF(AB17>=10,"C","D"))) -> D
A18: 9 | C18: 0 | D18: 0 | E18: 0 | F18: 0 | G18: =SUM(C18:F18) -> 0 | H18: 0 | I18: 0 | J18: 0 | K18: 0 | L18: =SUM(H18:K18) -> 0 | M18: 0 | N18: 0 | O18: 0 | P18: 0 | Q18: =SUM(M18:P18) -> 0 | R18: 0 | S18: 0 | T18: 0 | U18: 0 | V18: =SUM(R18:U18) -> 0 | W18: 0 | X18: 0 | Y18: 0 | Z18: 0 | AA18: =SUM(W18:Z18) -> 0 | AB18: =G18+L18+Q18+AA18+AA18 -> 0 | AC18: =IF(AB18>=20,"A",IF(AB18>=15,"B",IF(AB18>=10,"C","D"))) -> D
A19: 10 | C19: 0 | D19: 0 | E19: 0 | F19: 0 | G19: =SUM(C19:F19) -> 0 | H19: 0 | I19: 0 | J19: 0 | K19: 0 | L19: =SUM(H19:K19) -> 0 | M19: 0 | N19: 0 | O19: 0 | P19: 0 | Q19: =SUM(M19:P19) -> 0 | R19: 0 | S19: 0 | T19: 0 | U19: 0 | V19: =SUM(R19:U19) -> 0 | W19: 0 | X19: 0 | Y19: 0 | Z19: 0 | AA19: =SUM(W19:Z19) -> 0 | AB19: =G19+L19+Q19+AA19+AA19 -> 0 | AC19: =IF(AB19>=20,"A",IF(AB19>=15,"B",IF(AB19>=10,"C","D"))) -> D
A20: 11 | C20: 0 | D20: 0 | E20: 0 | F20: 0 | G20: =SUM(C20:F20) -> 0 | H20: 0 | I20: 0 | J20: 0 | K20: 0 | L20: =SUM(H20:K20) -> 0 | M20: 0 | N20: 0 | O20: 0 | P20: 0 | Q20: =SUM(M20:P20) -> 0 | R20: 0 | S20: 0 | T20: 0 | U20: 0 | V20: =SUM(R20:U20) -> 0 | W20: 0 | X20: 0 | Y20: 0 | Z20: 0 | AA20: =SUM(W20:Z20) -> 0 | AB20: =G20+L20+Q20+AA20+AA20 -> 0 | AC20: =IF(AB20>=20,"A",IF(AB20>=15,"B",IF(AB20>=10,"C","D"))) -> D
A21: 12 | C21: 0 | D21: 0 | E21: 0 | F21: 0 | G21: =SUM(C21:F21) -> 0 | H21: 0 | I21: 0 | J21: 0 | K21: 0 | L21: =SUM(H21:K21) -> 0 | M21: 0 | N21: 0 | O21: 0 | P21: 0 | Q21: =SUM(M21:P21) -> 0 | R21: 0 | S21: 0 | T21: 0 | U21: 0 | V21: =SUM(R21:U21) -> 0 | W21: 0 | X21: 0 | Y21: 0 | Z21: 0 | AA21: =SUM(W21:Z21) -> 0 | AB21: =G21+L21+Q21+AA21+AA21 -> 0 | AC21: =IF(AB21>=20,"A",IF(AB21>=15,"B",IF(AB21>=10,"C","D"))) -> D
... A59: 50 | C59: 0 | D59: 0 | E59: 0 | F59: 0 | G59: =SUM(C59:F59) -> 0 | H59: 0 | I59: 0 | J59: 0 | K59: 0 | L59: =SUM(H59:K59) -> 0 | M59: 0 | N59: 0 | O59: 0 | P59: 0 | Q59: =SUM(M59:P59) -> 0 | R59: 0 | S59: 0 | T59: 0 | U59: 0 | V59: =SUM(R59:U59) -> 0 | W59: 0 | X59: 0 | Y59: 0 | Z59: 0 | AA59: =SUM(W59:Z59) -> 0 | AB59: =G59+L59+Q59+AA59+AA59 -> 0 | AC59: =IF(AB59>=20,"A",IF(AB59>=15,"B",IF(AB59>=10,"C","D"))) -> D

Sheet VI-LP-4
A1: Week 4
A2: Fun with Cat Sprite - Controlling the Cat
A3: Annexure II
A4: Evaluation Rubrics
A5: Assessment Skill
A6: Roll No | B6: Name of the Student | C6: Discovery | H6: Understanding/ Problem Solving | M6: Completion of Tasks | R6: Interest/Motivation | W6: Team Work | AB6: LP-4
C7: Beginner (25%) | D7: Needs Improvement (50%) | E7: Comfortable (75%) | F7: Skilled (100%) | H7: Beginner (25%) | I7: Needs Improvement (50%) | J7: Comfortable (75%) | K7: Skilled (100%) | M7: Beginner (25%) | N7: Needs Improvement (50%) | O7: Comfortable (75%) | P7: Skilled (100%) | R7: Beginner (25%) | S7: Needs Improvement (50%) | T7: Comfortable (75%) | U7: Skilled (100%) | W7: Beginner (25%) | X7: Needs Improvement (50%) | Y7: Comfortable (75%) | Z7: Skilled (100%)
C8: It was a challenge for the student to find the blocks in the palette. | D8: The student was able to find some blocks, however, required help for discovering the others. | E8: The student found all the required blocks without any difficulty. | F8: The student was not only able to discover all the blocks in the palette but also explored other blocks in the palette. | H8: The student found it a challenge to understand the task. | I8: The student partially understood the task. | J8: The student could understand and partially explain the task. | K8: The student was quick to understand the task and could explain the same with clarity. | M8: The student could not get a solution within the given time. | N8: The student struggled to get a solution for the first task. | O8: The student got a solution for the first task but struggled with further tasks. | P8: The student could get the solution for most of the tasks and also experimented new tasks. | R8: The student showed very little interest in the activity. | S8: The student displayed fair bit of interest in the activity. | T8: The student participated in the activity with interest. | U8: The student was excited about performing the activity. | W8: The student was a passive member of the team. | X8: The student was considering all the opinions of the team members. | Y8: The student was able to filter and go ahead with the right opinion provided by the teammates | Z8: The student completed his/her work and also helped others team members by solving their difficulties wherever possible.
C9: 2 | D9: 3 | E9: 4 | F9: 5 | G9: Total/5 | H9: 2 | I9: 3 | J9: 4 | K9: 5 | L9: Total/5 | M9: 2 | N9: 3 | O9: 4 | P9: 5 | Q9: Total/5 | R9: 2 | S9: 3 | T9: 4 | U9: 5 | V9: Total/5 | W9: 2 | X9: 3 | Y9: 4 | Z9: 5 | AA9: Total/5 | AB9: Grand Total/25 | AC9: Grade
A10: 1 | C10: 0 | D10: 0 | E10: 0 | F10: 0 | G10: =SUM(C10:F10) -> 0 | H10: 0 | I10: 0 | J10: 0 | K10: 0 | L10: =SUM(H10:K10) -> 0 | M10: 0 | N10: 0 | O10: 0 | P10: 0 | Q10: =SUM(M10:P10) -> 0 | R10: 0 | S10: 0 | T10: 0 | U10: 0 | V10: =SUM(R10:U10) -> 0 | W10: 0 | X10: 0 | Y10: 0 | Z10: 0 | AA10: =SUM(W10:Z10) -> 0 | AB10: =G10+L10+Q10+AA10+AA10 -> 0 | AC10: =IF(AB10>=20,"A",IF(AB10>=15,"B",IF(AB10>=10,"C","D"))) -> D
A11: 2 | C11: 0 | D11: 0 | E11: 0 | F11: 0 | G11: =SUM(C11:F11) -> 0 | H11: 0 | I11: 0 | J11: 0 | K11: 0 | L11: =SUM(H11:K11) -> 0 | M11: 0 | N11: 0 | O11: 0 | P11: 0 | Q11: =SUM(M11:P11) -> 0 | R11: 0 | S11: 0 | T11: 0 | U11: 0 | V11: =SUM(R11:U11) -> 0 | W11: 0 | X11: 0 | Y11: 0 | Z11: 0 | AA11: =SUM(W11:Z11) -> 0 | AB11: =G11+L11+Q11+AA11+AA11 -> 0 | AC11: =IF(AB11>=20,"A",IF(AB11>=15,"B",IF(AB11>=10,"C","D"))) -> D
A12: 3 | C12: 0 | D12: 0 | E12: 0 | F12: 0 | G12: =SUM(C12:F12) -> 0 | H12: 0 | I12: 0 | J12: 0 | K12: 0 | L12: =SUM(H12:K12) -> 0 | M12: 0 | N12: 0 | O12: 0 | P12: 0 | Q12: =SUM(M12:P12) -> 0 | R12: 0 | S12: 0 | T12: 0 | U12: 0 | V12: =SUM(R12:U12) -> 0 | W12: 0 | X12: 0 | Y12: 0 | Z12: 0 | AA12: =SUM(W12:Z12) -> 0 | AB12: =G12+L12+Q12+AA12+AA12 -> 0 | AC12: =IF(AB12>=20,"A",IF(AB12>=15,"B",IF(AB12>=10,"C","D"))) -> D
A13: 4 | C13: 0 | D13: 0 | E13: 0 | F13: 0 | G13: =SUM(C13:F13) -> 0 | H13: 0 | I13: 0 | J13: 0 | K13: 0 | L13: =SUM(H13:K13) -> 0 | M13: 0 | N13: 0 | O13: 0 | P13: 0 | Q13: =SUM(M13:P13) -> 0 | R13: 0 | S13: 0 | T13: 0 | U13: 0 | V13: =SUM(R13:U13) -> 0 | W13: 0 | X13: 0 | Y13: 0 | Z13: 0 | AA13: =SUM(W13:Z13) -> 0 | AB13: =G13+L13+Q13+AA13+AA13 -> 0 | AC13: =IF(AB13>=20,"A",IF(AB13>=15,"B",IF(AB13>=10,"C","D"))) -> D
A14: 5 | C14: 0 | D14: 0 | E14: 0 | F14: 0 | G14: =SUM(C14:F14) -> 0 | H14: 0 | I14: 0 | J14: 0 | K14: 0 | L14: =SUM(H14:K14) -> 0 | M14: 0 | N14: 0 | O14: 0 | P14: 0 | Q14: =SUM(M14:P14) -> 0 | R14: 0 | S14: 0 | T14: 0 | U14: 0 | V14: =SUM(R14:U14) -> 0 | W14: 0 | X14: 0 | Y14: 0 | Z14: 0 | AA14: =SUM(W14:Z14) -> 0 | AB14: =G14+L14+Q14+AA14+AA14 -> 0 | AC14: =IF(AB14>=20,"A",IF(AB14>=15,"B",IF(AB14>=10,"C","D"))) -> D
A15: 6 | C15: 0 | D15: 0 | E15: 0 | F15: 0 | G15: =SUM(C15:F15) -> 0 | H15: 0 | I15: 0 | J15: 0 | K15: 0 | L15: =SUM(H15:K15) -> 0 | M15: 0 | N15: 0 | O15: 0 | P15: 0 | Q15: =SUM(M15:P15) -> 0 | R15: 0 | S15: 0 | T15: 0 | U15: 0 | V15: =SUM(R15:U15) -> 0 | W15: 0 | X15: 0 | Y15: 0 | Z15: 0 | AA15: =SUM(W15:Z15) -> 0 | AB15: =G15+L15+Q15+AA15+AA15 -> 0 | AC15: =IF(AB15>=20,"A",IF(AB15>=15,"B",IF(AB15>=10,"C","D"))) -> D
A16: 7 | C16: 0 | D16: 0 | E16: 0 | F16: 0 | G16: =SUM(C16:F16) -> 0 | H16: 0 | I16: 0 | J16: 0 | K16: 0 | L16: =SUM(H16:K16) -> 0 | M16: 0 | N16: 0 | O16: 0 | P16: 0 | Q16: =SUM(M16:P16) -> 0 | R16: 0 | S16: 0 | T16: 0 | U16: 0 | V16: =SUM(R16:U16) -> 0 | W16: 0 | X16: 0 | Y16: 0 | Z16: 0 | AA16: =SUM(W16:Z16) -> 0 | AB16: =G16+L16+Q16+AA16+AA16 -> 0 | AC16: =IF(AB16>=20,"A",IF(AB16>=15,"B",IF(AB16>=10,"C","D"))) -> D
A17: 8 | C17: 0 | D17: 0 | E17: 0 | F17: 0 | G17: =SUM(C17:F17) -> 0 | H17: 0 | I17: 0 | J17: 0 | K17: 0 | L17: =SUM(H17:K17) -> 0 | M17: 0 | N17: 0 | O17: 0 | P17: 0 | Q17: =SUM(M17:P17) -> 0 | R17: 0 | S17: 0 | T17: 0 | U17: 0 | V17: =SUM(R17:U17) -> 0 | W17: 0 | X17: 0 | Y17: 0 | Z17: 0 | AA17: =SUM(W17:Z17) -> 0 | AB17: =G17+L17+Q17+AA17+AA17 -> 0 | AC17: =IF(AB17>=20,"A",IF(AB17>=15,"B",IF(AB17>=10,"C","D"))) -> D
A18: 9 | C18: 0 | D18: 0 | E18: 0 | F18: 0 | G18: =SUM(C18:F18) -> 0 | H18: 0 | I18: 0 | J18: 0 | K18: 0 | L18: =SUM(H18:K18) -> 0 | M18: 0 | N18: 0 | O18: 0 | P18: 0 | Q18: =SUM(M18:P18) -> 0 | R18: 0 | S18: 0 | T18: 0 | U18: 0 | V18: =SUM(R18:U18) -> 0 | W18: 0 | X18: 0 | Y18: 0 | Z18: 0 | AA18: =SUM(W18:Z18) -> 0 | AB18: =G18+L18+Q18+AA18+AA18 -> 0 | AC18: =IF(AB18>=20,"A",IF(AB18>=15,"B",IF(AB18>=10,"C","D"))) -> D
A19: 10 | C19: 0 | D19: 0 | E19: 0 | F19: 0 | G19: =SUM(C19:F19) -> 0 | H19: 0 | I19: 0 | J19: 0 | K19: 0 | L19: =SUM(H19:K19) -> 0 | M19: 0 | N19: 0 | O19: 0 | P19: 0 | Q19: =SUM(M19:P19) -> 0 | R19: 0 | S19: 0 | T19: 0 | U19: 0 | V19: =SUM(R19:U19) -> 0 | W19: 0 | X19: 0 | Y19: 0 | Z19: 0 | AA19: =SUM(W19:Z19) -> 0 | AB19: =G19+L19+Q19+AA19+AA19 -> 0 | AC19: =IF(AB19>=20,"A",IF(AB19>=15,"B",IF(AB19>=10,"C","D"))) -> D
A20: 11 | C20: 0 | D20: 0 | E20: 0 | F20: 0 | G20: =SUM(C20:F20) -> 0 | H20: 0 | I20: 0 | J20: 0 | K20: 0 | L20: =SUM(H20:K20) -> 0 | M20: 0 | N20: 0 | O20: 0 | P20: 0 | Q20: =SUM(M20:P20) -> 0 | R20: 0 | S20: 0 | T20: 0 | U20: 0 | V20: =SUM(R20:U20) -> 0 | W20: 0 | X20: 0 | Y20: 0 | Z20: 0 | AA20: =SUM(W20:Z20) -> 0 | AB20: =G20+L20+Q20+AA20+AA20 -> 0 | AC20: =IF(AB20>=20,"A",IF(AB20>=15,"B",IF(AB20>=10,"C","D"))) -> D
A21: 12 | C21: 0 | D21: 0 | E21: 0 | F21: 0 | G21: =SUM(C21:F21) -> 0 | H21: 0 | I21: 0 | J21: 0 | K21: 0 | L21: =SUM(H21:K21) -> 0 | M21: 0 | N21: 0 | O21: 0 | P21: 0 | Q21: =SUM(M21:P21) -> 0 | R21: 0 | S21: 0 | T21: 0 | U21: 0 | V21: =SUM(R21:U21) -> 0 | W21: 0 | X21: 0 | Y21: 0 | Z21: 0 | AA21: =SUM(W21:Z21) -> 0 | AB21: =G21+L21+Q21+AA21+AA21 -> 0 | AC21: =IF(AB21>=20,"A",IF(AB21>=15,"B",IF(AB21>=10,"C","D"))) -> D
... A59: 50 | C59: 0 | D59: 0 | E59: 0 | F59: 0 | G59: =SUM(C59:F59) -> 0 | H59: 0 | I59: 0 | J59: 0 | K59: 0 | L59: =SUM(H59:K59) -> 0 | M59: 0 | N59: 0 | O59: 0 | P59: 0 | Q59: =SUM(M59:P59) -> 0 | R59: 0 | S59: 0 | T59: 0 | U59: 0 | V59: =SUM(R59:U59) -> 0 | W59: 0 | X59: 0 | Y59: 0 | Z59: 0 | AA59: =SUM(W59:Z59) -> 0 | AB59: =G59+L59+Q59+AA59+AA59 -> 0 | AC59: =IF(AB59>=20,"A",IF(AB59>=15,"B",IF(AB59>=10,"C","D"))) -> D

Sheet VI-LP-5
A1: Week 5
A2: Fun with Cat Sprite - Chasing the Mouse
A3: Annexure II
A4: Evaluation Rubrics
A5: Assessment Skill
A6: Roll No | B6: Name of the Student | C6: Discovery | H6: Understanding/ Problem | M6: Completion of Tasks | R6: Interest/Motivation | W6: Team Work | AB6: LP-5
C7: Beginner (25%) | D7: Needs Improvement (50%) | E7: Comfortable (75%) | F7: Skilled (100%) | H7: Beginner (25%) | I7: Needs Improvement (50%) | J7: Comfortable (75%) | K7: Skilled (100%) | M7: Beginner (25%) | N7: Needs Improvement (50%) | O7: Comfortable (75%) | P7: Skilled (100%) | R7: Beginner (25%) | S7: Needs Improvement (50%) | T7: Comfortable (75%) | U7: Skilled (100%) | W7: Beginner (25%) | X7: Needs Improvement (50%) | Y7: Comfortable (75%) | Z7: Skilled (100%)
C8: It was a challenge for the student to find the blocks in the palette. | D8: The student was able to find some blocks, however, required help for discovering the others. | E8: The student found all the required blocks without any difficulty. | F8: The student was not only able to discover all the blocks in the palette but also explored other blocks in the palette. | H8: The student found it a challenge to understand the task. | I8: The student partially understood the task. | J8: The student could understand and partially explain the task. | K8: The student was quick to understand the task and could explain the same with clarity. | M8: The student could not get a solution within the given time. | N8: The student struggled to get a solution for the first task. | O8: The student got a solution for the first task but struggled with further tasks. | P8: The student could get the solution for most of the tasks easily and also experimented new tasks. | R8: The student showed very little interest in the activity. | S8: The student displayed a fair bit of interest in the activity. | T8: The student participated in the activity with interest. | U8: The student was excited about performing the activity. | W8: The student was a passive member of the team. | X8: The student was considering all the opinions of the team members. | Y8: The student was able to filter and go ahead with the right opinion provided by the teammates | Z8: The student completed his/her work and also helped others team members by solving their difficulties wherever possible.
C9: 2 | D9: 3 | E9: 4 | F9: 5 | G9: Total/5 | H9: 2 | I9: 3 | J9: 4 | K9: 5 | L9: Total/5 | M9: 2 | N9: 3 | O9: 4 | P9: 5 | Q9: Total/5 | R9: 2 | S9: 3 | T9: 4 | U9: 5 | V9: Total/5 | W9: 2 | X9: 3 | Y9: 4 | Z9: 5 | AA9: Total/5 | AB9: Grand Total/25 | AC9: Grade
A10: 1 | C10: 0 | D10: 0 | E10: 0 | F10: 0 | G10: =SUM(C10:F10) -> 0 | H10: 0 | I10: 0 | J10: 0 | K10: 0 | L10: =SUM(H10:K10) -> 0 | M10: 0 | N10: 0 | O10: 0 | P10: 0 | Q10: =SUM(M10:P10) -> 0 | R10: 0 | S10: 0 | T10: 0 | U10: 0 | V10: =SUM(R10:U10) -> 0 | W10: 0 | X10: 0 | Y10: 0 | Z10: 0 | AA10: =SUM(W10:Z10) -> 0 | AB10: =G10+L10+Q10+AA10+AA10 -> 0 | AC10: =IF(AB10>=20,"A",IF(AB10>=15,"B",IF(AB10>=10,"C","D"))) -> D
A11: 2 | C11: 0 | D11: 0 | E11: 0 | F11: 0 | G11: =SUM(C11:F11) -> 0 | H11: 0 | I11: 0 | J11: 0 | K11: 0 | L11: =SUM(H11:K11) -> 0 | M11: 0 | N11: 0 | O11: 0 | P11: 0 | Q11: =SUM(M11:P11) -> 0 | R11: 0 | S11: 0 | T11: 0 | U11: 0 | V11: =SUM(R11:U11) -> 0 | W11: 0 | X11: 0 | Y11: 0 | Z11: 0 | AA11: =SUM(W11:Z11) -> 0 | AB11: =G11+L11+Q11+AA11+AA11 -> 0 | AC11: =IF(AB11>=20,"A",IF(AB11>=15,"B",IF(AB11>=10,"C","D"))) -> D
A12: 3 | C12: 0 | D12: 0 | E12: 0 | F12: 0 | G12: =SUM(C12:F12) -> 0 | H12: 0 | I12: 0 | J12: 0 | K12: 0 | L12: =SUM(H12:K12) -> 0 | M12: 0 | N12: 0 | O12: 0 | P12: 0 | Q12: =SUM(M12:P12) -> 0 | R12: 0 | S12: 0 | T12: 0 | U12: 0 | V12: =SUM(R12:U12) -> 0 | W12: 0 | X12: 0 | Y12: 0 | Z12: 0 | AA12: =SUM(W12:Z12) -> 0 | AB12: =G12+L12+Q12+AA12+AA12 -> 0 | AC12: =IF(AB12>=20,"A",IF(AB12>=15,"B",IF(AB12>=10,"C","D"))) -> D
A13: 4 | C13: 0 | D13: 0 | E13: 0 | F13: 0 | G13: =SUM(C13:F13) -> 0 | H13: 0 | I13: 0 | J13: 0 | K13: 0 | L13: =SUM(H13:K13) -> 0 | M13: 0 | N13: 0 | O13: 0 | P13: 0 | Q13: =SUM(M13:P13) -> 0 | R13: 0 | S13: 0 | T13: 0 | U13: 0 | V13: =SUM(R13:U13) -> 0 | W13: 0 | X13: 0 | Y13: 0 | Z13: 0 | AA13: =SUM(W13:Z13) -> 0 | AB13: =G13+L13+Q13+AA13+AA13 -> 0 | AC13: =IF(AB13>=20,"A",IF(AB13>=15,"B",IF(AB13>=10,"C","D"))) -> D
A14: 5 | C14: 0 | D14: 0 | E14: 0 | F14: 0 | G14: =SUM(C14:F14) -> 0 | H14: 0 | I14: 0 | J14: 0 | K14: 0 | L14: =SUM(H14:K14) -> 0 | M14: 0 | N14: 0 | O14: 0 | P14: 0 | Q14: =SUM(M14:P14) -> 0 | R14: 0 | S14: 0 | T14: 0 | U14: 0 | V14: =SUM(R14:U14) -> 0 | W14: 0 | X14: 0 | Y14: 0 | Z14: 0 | AA14: =SUM(W14:Z14) -> 0 | AB14: =G14+L14+Q14+AA14+AA14 -> 0 | AC14: =IF(AB14>=20,"A",IF(AB14>=15,"B",IF(AB14>=10,"C","D"))) -> D
A15: 6 | C15: 0 | D15: 0 | E15: 0 | F15: 0 | G15: =SUM(C15:F15) -> 0 | H15: 0 | I15: 0 | J15: 0 | K15: 0 | L15: =SUM(H15:K15) -> 0 | M15: 0 | N15: 0 | O15: 0 | P15: 0 | Q15: =SUM(M15:P15) -> 0 | R15: 0 | S15: 0 | T15: 0 | U15: 0 | V15: =SUM(R15:U15) -> 0 | W15: 0 | X15: 0 | Y15: 0 | Z15: 0 | AA15: =SUM(W15:Z15) -> 0 | AB15: =G15+L15+Q15+AA15+AA15 -> 0 | AC15: =IF(AB15>=20,"A",IF(AB15>=15,"B",IF(AB15>=10,"C","D"))) -> D
A16: 7 | C16: 0 | D16: 0 | E16: 0 | F16: 0 | G16: =SUM(C16:F16) -> 0 | H16: 0 | I16: 0 | J16: 0 | K16: 0 | L16: =SUM(H16:K16) -> 0 | M16: 0 | N16: 0 | O16: 0 | P16: 0 | Q16: =SUM(M16:P16) -> 0 | R16: 0 | S16: 0 | T16: 0 | U16: 0 | V16: =SUM(R16:U16) -> 0 | W16: 0 | X16: 0 | Y16: 0 | Z16: 0 | AA16: =SUM(W16:Z16) -> 0 | AB16: =G16+L16+Q16+AA16+AA16 -> 0 | AC16: =IF(AB16>=20,"A",IF(AB16>=15,"B",IF(AB16>=10,"C","D"))) -> D
A17: 8 | C17: 0 | D17: 0 | E17: 0 | F17: 0 | G17: =SUM(C17:F17) -> 0 | H17: 0 | I17: 0 | J17: 0 | K17: 0 | L17: =SUM(H17:K17) -> 0 | M17: 0 | N17: 0 | O17: 0 | P17: 0 | Q17: =SUM(M17:P17) -> 0 | R17: 0 | S17: 0 | T17: 0 | U17: 0 | V17: =SUM(R17:U17) -> 0 | W17: 0 | X17: 0 | Y17: 0 | Z17: 0 | AA17: =SUM(W17:Z17) -> 0 | AB17: =G17+L17+Q17+AA17+AA17 -> 0 | AC17: =IF(AB17>=20,"A",IF(AB17>=15,"B",IF(AB17>=10,"C","D"))) -> D
A18: 9 | C18: 0 | D18: 0 | E18: 0 | F18: 0 | G18: =SUM(C18:F18) -> 0 | H18: 0 | I18: 0 | J18: 0 | K18: 0 | L18: =SUM(H18:K18) -> 0 | M18: 0 | N18: 0 | O18: 0 | P18: 0 | Q18: =SUM(M18:P18) -> 0 | R18: 0 | S18: 0 | T18: 0 | U18: 0 | V18: =SUM(R18:U18) -> 0 | W18: 0 | X18: 0 | Y18: 0 | Z18: 0 | AA18: =SUM(W18:Z18) -> 0 | AB18: =G18+L18+Q18+AA18+AA18 -> 0 | AC18: =IF(AB18>=20,"A",IF(AB18>=15,"B",IF(AB18>=10,"C","D"))) -> D
A19: 10 | C19: 0 | D19: 0 | E19: 0 | F19: 0 | G19: =SUM(C19:F19) -> 0 | H19: 0 | I19: 0 | J19: 0 | K19: 0 | L19: =SUM(H19:K19) -> 0 | M19: 0 | N19: 0 | O19: 0 | P19: 0 | Q19: =SUM(M19:P19) -> 0 | R19: 0 | S19: 0 | T19: 0 | U19: 0 | V19: =SUM(R19:U19) -> 0 | W19: 0 | X19: 0 | Y19: 0 | Z19: 0 | AA19: =SUM(W19:Z19) -> 0 | AB19: =G19+L19+Q19+AA19+AA19 -> 0 | AC19: =IF(AB19>=20,"A",IF(AB19>=15,"B",IF(AB19>=10,"C","D"))) -> D
A20: 11 | C20: 0 | D20: 0 | E20: 0 | F20: 0 | G20: =SUM(C20:F20) -> 0 | H20: 0 | I20: 0 | J20: 0 | K20: 0 | L20: =SUM(H20:K20) -> 0 | M20: 0 | N20: 0 | O20: 0 | P20: 0 | Q20: =SUM(M20:P20) -> 0 | R20: 0 | S20: 0 | T20: 0 | U20: 0 | V20: =SUM(R20:U20) -> 0 | W20: 0 | X20: 0 | Y20: 0 | Z20: 0 | AA20: =SUM(W20:Z20) -> 0 | AB20: =G20+L20+Q20+AA20+AA20 -> 0 | AC20: =IF(AB20>=20,"A",IF(AB20>=15,"B",IF(AB20>=10,"C","D"))) -> D
A21: 12 | C21: 0 | D21: 0 | E21: 0 | F21: 0 | G21: =SUM(C21:F21) -> 0 | H21: 0 | I21: 0 | J21: 0 | K21: 0 | L21: =SUM(H21:K21) -> 0 | M21: 0 | N21: 0 | O21: 0 | P21: 0 | Q21: =SUM(M21:P21) -> 0 | R21: 0 | S21: 0 | T21: 0 | U21: 0 | V21: =SUM(R21:U21) -> 0 | W21: 0 | X21: 0 | Y21: 0 | Z21: 0 | AA21: =SUM(W21:Z21) -> 0 | AB21: =G21+L21+Q21+AA21+AA21 -> 0 | AC21: =IF(AB21>=20,"A",IF(AB21>=15,"B",IF(AB21>=10,"C","D"))) -> D
... A59: 50 | C59: 0 | D59: 0 | E59: 0 | F59: 0 | G59: =SUM(C59:F59) -> 0 | H59: 0 | I59: 0 | J59: 0 | K59: 0 | L59: =SUM(H59:K59) -> 0 | M59: 0 | N59: 0 | O59: 0 | P59: 0 | Q59: =SUM(M59:P59) -> 0 | R59: 0 | S59: 0 | T59: 0 | U59: 0 | V59: =SUM(R59:U59) -> 0 | W59: 0 | X59: 0 | Y59: 0 | Z59: 0 | AA59: =SUM(W59:Z59) -> 0 | AB59: =G59+L59+Q59+AA59+AA59 -> 0 | AC59: =IF(AB59>=20,"A",IF(AB59>=15,"B",IF(AB59>=10,"C","D"))) -> D

Sheet VI-LP-6
A1: Week 6
A2: Fun with Cat Sprite - Cat Annimation
A3: Annexure II
A4: Evaluation Rubrics
A5: Assessment Skill
A6: Roll No | B6: Name of the Student | C6: Discovery | H6: Understanding/ Problem Solving | M6: Completion of Tasks | R6: Interest/Motivation | W6: Team Work | AB6: LP-6
C7: Beginner (25%) | D7: Needs Improvement (50%) | E7: Comfortable (75%) | F7: Skilled (100%) | H7: Beginner (25%) | I7: Needs Improvement (50%) | J7: Comfortable (75%) | K7: Skilled (100%) | M7: Beginner (25%) | N7: Needs Improvement (50%) | O7: Comfortable (75%) | P7: Skilled (100%) | R7: Beginner (25%) | S7: Needs Improvement (50%) | T7: Comfortable (75%) | U7: Skilled (100%) | W7: Beginner (25%) | X7: Needs Improvement (50%) | Y7: Comfortable (75%) | Z7: Skilled (100%)
C8: It was a challenge for the student to find the blocks in the palette. | D8: The student was able to find some blocks, however, required help for discovering the others. | E8: The student found all the required blocks without any difficulty. | F8: The student was not only able to discover all the blocks in the palette but also explored other blocks in the palette. | H8: The student found it a challenge to understand the task. | I8: The student partially understood the task. | J8: The student could understand and partially explain the task. | K8: The student was quick to understand the task and could explain the same with clarity. | M8: The student could not get a solution within the given time. | N8: The student struggled to get a solution for the first task. | O8: The student got a solution for the first task but struggled with further tasks. | P8: The student could get the solution for most of the tasks easily and experimented new tasks. | R8: The student showed very little interest in the activity. | S8: The student displayed a fair bit of interest in the activity. | T8: The student participated in the activity with interest. | U8: The student was excited about performing the activity. | W8: The student was a passive member of the team. | X8: The student was considering all the opinions of the team members. | Y8: The student was able to filter and go ahead with the right opinion provided by the teammates | Z8: The student completed his/her work and also helped others team members by solving their difficulties wherever possible.
C9: 2 | D9: 3 | E9: 4 | F9: 5 | G9: Total/5 | H9: 2 | I9: 3 | J9: 4 | K9: 5 | L9: Total/5 | M9: 2 | N9: 3 | O9: 4 | P9: 5 | Q9: Total/5 | R9: 2 | S9: 3 | T9: 4 | U9: 5 | V9: Total/5 | W9: 2 | X9: 3 | Y9: 4 | Z9: 5 | AA9: Total/5 | AB9: Grand Total/25 | AC9: Grade
A10: 1 | C10: 0 | D10: 0 | E10: 0 | F10: 0 | G10: =SUM(C10:F10) -> 0 | H10: 0 | I10: 0 | J10: 0 | K10: 0 | L10: =SUM(H10:K10) -> 0 | M10: 0 | N10: 0 | O10: 0 | P10: 0 | Q10: =SUM(M10:P10) -> 0 | R10: 0 | S10: 0 | T10: 0 | U10: 0 | V10: =SUM(R10:U10) -> 0 | W10: 0 | X10: 0 | Y10: 0 | Z10: 0 | AA10: =SUM(W10:Z10) -> 0 | AB10: =G10+L10+Q10+AA10+AA10 -> 0 | AC10: =IF(AB10>=20,"A",IF(AB10>=15,"B",IF(AB10>=10,"C","D"))) -> D
A11: 2 | C11: 0 | D11: 0 | E11: 0 | F11: 0 | G11: =SUM(C11:F11) -> 0 | H11: 0 | I11: 0 | J11: 0 | K11: 0 | L11: =SUM(H11:K11) -> 0 | M11: 0 | N11: 0 | O11: 0 | P11: 0 | Q11: =SUM(M11:P11) -> 0 | R11: 0 | S11: 0 | T11: 0 | U11: 0 | V11: =SUM(R11:U11) -> 0 | W11: 0 | X11: 0 | Y11: 0 | Z11: 0 | AA11: =SUM(W11:Z11) -> 0 | AB11: =G11+L11+Q11+AA11+AA11 -> 0 | AC11: =IF(AB11>=20,"A",IF(AB11>=15,"B",IF(AB11>=10,"C","D"))) -> D
A12: 3 | C12: 0 | D12: 0 | E12: 0 | F12: 0 | G12: =SUM(C12:F12) -> 0 | H12: 0 | I12: 0 | J12: 0 | K12: 0 | L12: =SUM(H12:K12) -> 0 | M12: 0 | N12: 0 | O12: 0 | P12: 0 | Q12: =SUM(M12:P12) -> 0 | R12: 0 | S12: 0 | T12: 0 | U12: 0 | V12: =SUM(R12:U12) -> 0 | W12: 0 | X12: 0 | Y12: 0 | Z12: 0 | AA12: =SUM(W12:Z12) -> 0 | AB12: =G12+L12+Q12+AA12+AA12 -> 0 | AC12: =IF(AB12>=20,"A",IF(AB12>=15,"B",IF(AB12>=10,"C","D"))) -> D
A13: 4 | C13: 0 | D13: 0 | E13: 0 | F13: 0 | G13: =SUM(C13:F13) -> 0 | H13: 0 | I13: 0 | J13: 0 | K13: 0 | L13: =SUM(H13:K13) -> 0 | M13: 0 | N13: 0 | O13: 0 | P13: 0 | Q13: =SUM(M13:P13) -> 0 | R13: 0 | S13: 0 | T13: 0 | U13: 0 | V13: =SUM(R13:U13) -> 0 | W13: 0 | X13: 0 | Y13: 0 | Z13: 0 | AA13: =SUM(W13:Z13) -> 0 | AB13: =G13+L13+Q13+AA13+AA13 -> 0 | AC13: =IF(AB13>=20,"A",IF(AB13>=15,"B",IF(AB13>=10,"C","D"))) -> D
A14: 5 | C14: 0 | D14: 0 | E14: 0 | F14: 0 | G14: =SUM(C14:F14) -> 0 | H14: 0 | I14: 0 | J14: 0 | K14: 0 | L14: =SUM(H14:K14) -> 0 | M14: 0 | N14: 0 | O14: 0 | P14: 0 | Q14: =SUM(M14:P14) -> 0 | R14: 0 | S14: 0 | T14: 0 | U14: 0 | V14: =SUM(R14:U14) -> 0 | W14: 0 | X14: 0 | Y14: 0 | Z14: 0 | AA14: =SUM(W14:Z14) -> 0 | AB14: =G14+L14+Q14+AA14+AA14 -> 0 | AC14: =IF(AB14>=20,"A",IF(AB14>=15,"B",IF(AB14>=10,"C","D"))) -> D
A15: 6 | C15: 0 | D15: 0 | E15: 0 | F15: 0 | G15: =SUM(C15:F15) -> 0 | H15: 0 | I15: 0 | J15: 0 | K15: 0 | L15: =SUM(H15:K15) -> 0 | M15: 0 | N15: 0 | O15: 0 | P15: 0 | Q15: =SUM(M15:P15) -> 0 | R15: 0 | S15: 0 | T15: 0 | U15: 0 | V15: =SUM(R15:U15) -> 0 | W15: 0 | X15: 0 | Y15: 0 | Z15: 0 | AA15: =SUM(W15:Z15) -> 0 | AB15: =G15+L15+Q15+AA15+AA15 -> 0 | AC15: =IF(AB15>=20,"A",IF(AB15>=15,"B",IF(AB15>=10,"C","D"))) -> D
A16: 7 | C16: 0 | D16: 0 | E16: 0 | F16: 0 | G16: =SUM(C16:F16) -> 0 | H16: 0 | I16: 0 | J16: 0 | K16: 0 | L16: =SUM(H16:K16) -> 0 | M16: 0 | N16: 0 | O16: 0 | P16: 0 | Q16: =SUM(M16:P16) -> 0 | R16: 0 | S16: 0 | T16: 0 | U16: 0 | V16: =SUM(R16:U16) -> 0 | W16: 0 | X16: 0 | Y16: 0 | Z16: 0 | AA16: =SUM(W16:Z16) -> 0 | AB16: =G16+L16+Q16+AA16+AA16 -> 0 | AC16: =IF(AB16>=20,"A",IF(AB16>=15,"B",IF(AB16>=10,"C","D"))) -> D
A17: 8 | C17: 0 | D17: 0 | E17: 0 | F17: 0 | G17: =SUM(C17:F17) -> 0 | H17: 0 | I17: 0 | J17: 0 | K17: 0 | L17: =SUM(H17:K17) -> 0 | M17: 0 | N17: 0 | O17: 0 | P17: 0 | Q17: =SUM(M17:P17) -> 0 | R17: 0 | S17: 0 | T17: 0 | U17: 0 | V17: =SUM(R17:U17) -> 0 | W17: 0 | X17: 0 | Y17: 0 | Z17: 0 | AA17: =SUM(W17:Z17) -> 0 | AB17: =G17+L17+Q17+AA17+AA17 -> 0 | AC17: =IF(AB17>=20,"A",IF(AB17>=15,"B",IF(AB17>=10,"C","D"))) -> D
A18: 9 | C18: 0 | D18: 0 | E18: 0 | F18: 0 | G18: =SUM(C18:F18) -> 0 | H18: 0 | I18: 0 | J18: 0 | K18: 0 | L18: =SUM(H18:K18) -> 0 | M18: 0 | N18: 0 | O18: 0 | P18: 0 | Q18: =SUM(M18:P18) -> 0 | R18: 0 | S18: 0 | T18: 0 | U18: 0 | V18: =SUM(R18:U18) -> 0 | W18: 0 | X18: 0 | Y18: 0 | Z18: 0 | AA18: =SUM(W18:Z18) -> 0 | AB18: =G18+L18+Q18+AA18+AA18 -> 0 | AC18: =IF(AB18>=20,"A",IF(AB18>=15,"B",IF(AB18>=10,"C","D"))) -> D
A19: 10 | C19: 0 | D19: 0 | E19: 0 | F19: 0 | G19: =SUM(C19:F19) -> 0 | H19: 0 | I19: 0 | J19: 0 | K19: 0 | L19: =SUM(H19:K19) -> 0 | M19: 0 | N19: 0 | O19: 0 | P19: 0 | Q19: =SUM(M19:P19) -> 0 | R19: 0 | S19: 0 | T19: 0 | U19: 0 | V19: =SUM(R19:U19) -> 0 | W19: 0 | X19: 0 | Y19: 0 | Z19: 0 | AA19: =SUM(W19:Z19) -> 0 | AB19: =G19+L19+Q19+AA19+AA19 -> 0 | AC19: =IF(AB19>=20,"A",IF(AB19>=15,"B",IF(AB19>=10,"C","D"))) -> D
A20: 11 | C20: 0 | D20: 0 | E20: 0 | F20: 0 | G20: =SUM(C20:F20) -> 0 | H20: 0 | I20: 0 | J20: 0 | K20: 0 | L20: =SUM(H20:K20) -> 0 | M20: 0 | N20: 0 | O20: 0 | P20: 0 | Q20: =SUM(M20:P20) -> 0 | R20: 0 | S20: 0 | T20: 0 | U20: 0 | V20: =SUM(R20:U20) -> 0 | W20: 0 | X20: 0 | Y20: 0 | Z20: 0 | AA20: =SUM(W20:Z20) -> 0 | AB20: =G20+L20+Q20+AA20+AA20 -> 0 | AC20: =IF(AB20>=20,"A",IF(AB20>=15,"B",IF(AB20>=10,"C","D"))) -> D
A21: 12 | C21: 0 | D21: 0 | E21: 0 | F21: 0 | G21: =SUM(C21:F21) -> 0 | H21: 0 | I21: 0 | J21: 0 | K21: 0 | L21: =SUM(H21:K21) -> 0 | M21: 0 | N21: 0 | O21: 0 | P21: 0 | Q21: =SUM(M21:P21) -> 0 | R21: 0 | S21: 0 | T21: 0 | U21: 0 | V21: =SUM(R21:U21) -> 0 | W21: 0 | X21: 0 | Y21: 0 | Z21: 0 | AA21: =SUM(W21:Z21) -> 0 | AB21: =G21+L21+Q21+AA21+AA21 -> 0 | AC21: =IF(AB21>=20,"A",IF(AB21>=15,"B",IF(AB21>=10,"C","D"))) -> D
... A59: 50 | C59: 0 | D59: 0 | E59: 0 | F59: 0 | G59: =SUM(C59:F59) -> 0 | H59: 0 | I59: 0 | J59: 0 | K59: 0 | L59: =SUM(H59:K59) -> 0 | M59: 0 | N59: 0 | O59: 0 | P59: 0 | Q59: =SUM(M59:P59) -> 0 | R59: 0 | S59: 0 | T59: 0 | U59: 0 | V59: =SUM(R59:U59) -> 0 | W59: 0 | X59: 0 | Y59: 0 | Z59: 0 | AA59: =SUM(W59:Z59) -> 0 | AB59: =G59+L59+Q59+AA59+AA59 -> 0 | AC59: =IF(AB59>=20,"A",IF(AB59>=15,"B",IF(AB59>=10,"C","D"))) -> D

Sheet VI-LP-7
A1: Week 7
A2: Fun with Cat Sprite - Sound
A3: Annexure II
A4: Evaluation Rubrics
A5: Assessment Skill
A6: Roll No | B6: Name of the Student | C6: Discovery | H6: Understanding/ Problem | M6: Completion of Tasks | R6: Interest/Motivation | W6: Team Work | AB6: LP-7
C7: Beginner (25%) | D7: Needs Improvement (50%) | E7: Comfortable (75%) | F7: Skilled (100%) | H7: Beginner (25%) | I7: Needs Improvement (50%) | J7: Comfortable (75%) | K7: Skilled (100%) | M7: Beginner (25%) | N7: Needs Improvement (50%) | O7: Comfortable (75%) | P7: Skilled (100%) | R7: Beginner (25%) | S7: Needs Improvement (50%) | T7: Comfortable (75%) | U7: Skilled (100%) | W7: Beginner (25%) | X7: Needs Improvement (50%) | Y7: Comfortable (75%) | Z7: Skilled (100%)
C8: It was a challenge for the student to find and use the sound blocks from the palette. | D8: The student was able to find some sound blocks, however required help for discovering others. | E8: The student found all the required sound blocks without any difficulty. | F8: The student was not only able to discover all the sound blocks in the palette but also explored other musical notes in the sound extension palette. | H8: The student found it a challenge to understand the task. | I8: The student partially understood the task. | J8: The student could understand and partially explain the task. | K8: The student was quick to understand the task and could explain the same with clarity. | M8: The student could not get a solution within the given time. | N8: The student struggled to get a solution for the first task. | O8: The student got a solution for the first task but struggled a bit with further tasks. | P8: The student could get the solution for most of the tasks easily and experimented new tasks. | R8: The student showed very little interest in the activity. | S8: The student displayed a fair bit of interest in the activity. | T8: The student participated in the activity with interest. | U8: The student was excited about performing the activity. | W8: The student was a passive member of the team. | X8: The student was considering all the opinions of the team members. | Y8: The student was able to filter and go ahead with the right opinion provided by the teammates | Z8: The student completed his/her work and also helped others team members by solving their difficulties wherever possible.
C9: 2 | D9: 3 | E9: 4 | F9: 5 | G9: Total/5 | H9: 2 | I9: 3 | J9: 4 | K9: 5 | L9: Total/5 | M9: 2 | N9: 3 | O9: 4 | P9: 5 | Q9: Total/5 | R9: 2 | S9: 3 | T9: 4 | U9: 5 | V9: Total/5 | W9: 2 | X9: 3 | Y9: 4 | Z9: 5 | AA9: Total/5 | AB9: Grand Total/25 | AC9: Grade
A10: 1 | C10: 0 | D10: 0 | E10: 0 | F10: 0 | G10: =SUM(C10:F10) -> 0 | H10: 0 | I10: 0 | J10: 0 | K10: 0 | L10: =SUM(H10:K10) -> 0 | M10: 0 | N10: 0 | O10: 0 | P10: 0 | Q10: =SUM(M10:P10) -> 0 | R10: 0 | S10: 0 | T10: 0 | U10: 0 | V10: =SUM(R10:U10) -> 0 | W10: 0 | X10: 0 | Y10: 0 | Z10: 0 | AA10: =SUM(W10:Z10) -> 0 | AB10: =G10+L10+Q10+AA10+AA10 -> 0 | AC10: =IF(AB10>=20,"A",IF(AB10>=15,"B",IF(AB10>=10,"C","D"))) -> D
A11: 2 | C11: 0 | D11: 0 | E11: 0 | F11: 0 | G11: =SUM(C11:F11) -> 0 | H11: 0 | I11: 0 | J11: 0 | K11: 0 | L11: =SUM(H11:K11) -> 0 | M11: 0 | N11: 0 | O11: 0 | P11: 0 | Q11: =SUM(M11:P11) -> 0 | R11: 0 | S11: 0 | T11: 0 | U11: 0 | V11: =SUM(R11:U11) -> 0 | W11: 0 | X11: 0 | Y11: 0 | Z11: 0 | AA11: =SUM(W11:Z11) -> 0 | AB11: =G11+L11+Q11+AA11+AA11 -> 0 | AC11: =IF(AB11>=20,"A",IF(AB11>=15,"B",IF(AB11>=10,"C","D"))) -> D
A12: 3 | C12: 0 | D12: 0 | E12: 0 | F12: 0 | G12: =SUM(C12:F12) -> 0 | H12: 0 | I12: 0 | J12: 0 | K12: 0 | L12: =SUM(H12:K12) -> 0 | M12: 0 | N12: 0 | O12: 0 | P12: 0 | Q12: =SUM(M12:P12) -> 0 | R12: 0 | S12: 0 | T12: 0 | U12: 0 | V12: =SUM(R12:U12) -> 0 | W12: 0 | X12: 0 | Y12: 0 | Z12: 0 | AA12: =SUM(W12:Z12) -> 0 | AB12: =G12+L12+Q12+AA12+AA12 -> 0 | AC12: =IF(AB12>=20,"A",IF(AB12>=15,"B",IF(AB12>=10,"C","D"))) -> D
A13: 4 | C13: 0 | D13: 0 | E13: 0 | F13: 0 | G13: =SUM(C13:F13) -> 0 | H13: 0 | I13: 0 | J13: 0 | K13: 0 | L13: =SUM(H13:K13) -> 0 | M13: 0 | N13: 0 | O13: 0 | P13: 0 | Q13: =SUM(M13:P13) -> 0 | R13: 0 | S13: 0 | T13: 0 | U13: 0 | V13: =SUM(R13:U13) -> 0 | W13: 0 | X13: 0 | Y13: 0 | Z13: 0 | AA13: =SUM(W13:Z13) -> 0 | AB13: =G13+L13+Q13+AA13+AA13 -> 0 | AC13: =IF(AB13>=20,"A",IF(AB13>=15,"B",IF(AB13>=10,"C","D"))) -> D
A14: 5 | C14: 0 | D14: 0 | E14: 0 | F14: 0 | G14: =SUM(C14:F14) -> 0 | H14: 0 | I14: 0 | J14: 0 | K14: 0 | L14: =SUM(H14:K14) -> 0 | M14: 0 | N14: 0 | O14: 0 | P14: 0 | Q14: =SUM(M14:P14) -> 0 | R14: 0 | S14: 0 | T14: 0 | U14: 0 | V14: =SUM(R14:U14) -> 0 | W14: 0 | X14: 0 | Y14: 0 | Z14: 0 | AA14: =SUM(W14:Z14) -> 0 | AB14: =G14+L14+Q14+AA14+AA14 -> 0 | AC14: =IF(AB14>=20,"A",IF(AB14>=15,"B",IF(AB14>=10,"C","D"))) -> D
A15: 6 | C15: 0 | D15: 0 | E15: 0 | F15: 0 | G15: =SUM(C15:F15) -> 0 | H15: 0 | I15: 0 | J15: 0 | K15: 0 | L15: =SUM(H15:K15) -> 0 | M15: 0 | N15: 0 | O15: 0 | P15: 0 | Q15: =SUM(M15:P15) -> 0 | R15: 0 | S15: 0 | T15: 0 | U15: 0 | V15: =SUM(R15:U15) -> 0 | W15: 0 | X15: 0 | Y15: 0 | Z15: 0 | AA15: =SUM(W15:Z15) -> 0 | AB15: =G15+L15+Q15+AA15+AA15 -> 0 | AC15: =IF(AB15>=20,"A",IF(AB15>=15,"B",IF(AB15>=10,"C","D"))) -> D
A16: 7 | C16: 0 | D16: 0 | E16: 0 | F16: 0 | G16: =SUM(C16:F16) -> 0 | H16: 0 | I16: 0 | J16: 0 | K16: 0 | L16: =SUM(H16:K16) -> 0 | M16: 0 | N16: 0 | O16: 0 | P16: 0 | Q16: =SUM(M16:P16) -> 0 | R16: 0 | S16: 0 | T16: 0 | U16: 0 | V16: =SUM(R16:U16) -> 0 | W16: 0 | X16: 0 | Y16: 0 | Z16: 0 | AA16: =SUM(W16:Z16) -> 0 | AB16: =G16+L16+Q16+AA16+AA16 -> 0 | AC16: =IF(AB16>=20,"A",IF(AB16>=15,"B",IF(AB16>=10,"C","D"))) -> D
A17: 8 | C17: 0 | D17: 0 | E17: 0 | F17: 0 | G17: =SUM(C17:F17) -> 0 | H17: 0 | I17: 0 | J17: 0 | K17: 0 | L17: =SUM(H17:K17) -> 0 | M17: 0 | N17: 0 | O17: 0 | P17: 0 | Q17: =SUM(M17:P17) -> 0 | R17: 0 | S17: 0 | T17: 0 | U17: 0 | V17: =SUM(R17:U17) -> 0 | W17: 0 | X17: 0 | Y17: 0 | Z17: 0 | AA17: =SUM(W17:Z17) -> 0 | AB17: =G17+L17+Q17+AA17+AA17 -> 0 | AC17: =IF(AB17>=20,"A",IF(AB17>=15,"B",IF(AB17>=10,"C","D"))) -> D
A18: 9 | C18: 0 | D18: 0 | E18: 0 | F18: 0 | G18: =SUM(C18:F18) -> 0 | H18: 0 | I18: 0 | J18: 0 | K18: 0 | L18: =SUM(H18:K18) -> 0 | M18: 0 | N18: 0 | O18: 0 | P18: 0 | Q18: =SUM(M18:P18) -> 0 | R18: 0 | S18: 0 | T18: 0 | U18: 0 | V18: =SUM(R18:U18) -> 0 | W18: 0 | X18: 0 | Y18: 0 | Z18: 0 | AA18: =SUM(W18:Z18) -> 0 | AB18: =G18+L18+Q18+AA18+AA18 -> 0 | AC18: =IF(AB18>=20,"A",IF(AB18>=15,"B",IF(AB18>=10,"C","D"))) -> D
A19: 10 | C19: 0 | D19: 0 | E19: 0 | F19: 0 | G19: =SUM(C19:F19) -> 0 | H19: 0 | I19: 0 | J19: 0 | K19: 0 | L19: =SUM(H19:K19) -> 0 | M19: 0 | N19: 0 | O19: 0 | P19: 0 | Q19: =SUM(M19:P19) -> 0 | R19: 0 | S19: 0 | T19: 0 | U19: 0 | V19: =SUM(R19:U19) -> 0 | W19: 0 | X19: 0 | Y19: 0 | Z19: 0 | AA19: =SUM(W19:Z19) -> 0 | AB19: =G19+L19+Q19+AA19+AA19 -> 0 | AC19: =IF(AB19>=20,"A",IF(AB19>=15,"B",IF(AB19>=10,"C","D"))) -> D
A20: 11 | C20: 0 | D20: 0 | E20: 0 | F20: 0 | G20: =SUM(C20:F20) -> 0 | H20: 0 | I20: 0 | J20: 0 | K20: 0 | L20: =SUM(H20:K20) -> 0 | M20: 0 | N20: 0 | O20: 0 | P20: 0 | Q20: =SUM(M20:P20) -> 0 | R20: 0 | S20: 0 | T20: 0 | U20: 0 | V20: =SUM(R20:U20) -> 0 | W20: 0 | X20: 0 | Y20: 0 | Z20: 0 | AA20: =SUM(W20:Z20) -> 0 | AB20: =G20+L20+Q20+AA20+AA20 -> 0 | AC20: =IF(AB20>=20,"A",IF(AB20>=15,"B",IF(AB20>=10,"C","D"))) -> D
A21: 12 | C21: 0 | D21: 0 | E21: 0 | F21: 0 | G21: =SUM(C21:F21) -> 0 | H21: 0 | I21: 0 | J21: 0 | K21: 0 | L21: =SUM(H21:K21) -> 0 | M21: 0 | N21: 0 | O21: 0 | P21: 0 | Q21: =SUM(M21:P21) -> 0 | R21: 0 | S21: 0 | T21: 0 | U21: 0 | V21: =SUM(R21:U21) -> 0 | W21: 0 | X21: 0 | Y21: 0 | Z21: 0 | AA21: =SUM(W21:Z21) -> 0 | AB21: =G21+L21+Q21+AA21+AA21 -> 0 | AC21: =IF(AB21>=20,"A",IF(AB21>=15,"B",IF(AB21>=10,"C","D"))) -> D
... A59: 50 | C59: 0 | D59: 0 | E59: 0 | F59: 0 | G59: =SUM(C59:F59) -> 0 | H59: 0 | I59: 0 | J59: 0 | K59: 0 | L59: =SUM(H59:K59) -> 0 | M59: 0 | N59: 0 | O59: 0 | P59: 0 | Q59: =SUM(M59:P59) -> 0 | R59: 0 | S59: 0 | T59: 0 | U59: 0 | V59: =SUM(R59:U59) -> 0 | W59: 0 | X59: 0 | Y59: 0 | Z59: 0 | AA59: =SUM(W59:Z59) -> 0 | AB59: =G59+L59+Q59+AA59+AA59 -> 0 | AC59: =IF(AB59>=20,"A",IF(AB59>=15,"B",IF(AB59>=10,"C","D"))) -> D

Sheet VI-LP-8
A1: Week 8
A2: Worksheet and Exercise
A3: Annexure II
A4: Evaluation Rubrics
A5: Assessment Skill
A6: Roll No | B6: Name of the Student | C6: Discovery | H6: Understanding/ Problem Solving | M6: Completion of Tasks | R6: Interest/Motivation | W6: Team Work | AB6: LP-8
C7: Beginner (25%) | D7: Needs Improvement (50%) | E7: Comfortable (75%) | F7: Skilled (100%) | H7: Beginner (25%) | I7: Needs Improvement (50%) | J7: Comfortable (75%) | K7: Skilled (100%) | M7: Beginner (25%) | N7: Needs Improvement (50%) | O7: Comfortable (75%) | P7: Skilled (100%) | R7: Beginner (25%) | S7: Needs Improvement (50%) | T7: Comfortable (75%) | U7: Skilled (100%) | W7: Beginner (25%) | X7: Needs Improvement (50%) | Y7: Comfortable (75%) | Z7: Skilled (100%)
C8: It was a challenge for the student to find and use the various blocks required from the palette. | D8: The student was able to find some blocks, however required help for discovering others. | E8: The student found all the required blocks without any difficulty. | F8: The student was not only able to discover all the blocks in the palette but also explored other blocks like musical notes in the sound extension palette. | H8: The student found it a challenge to understand the task. | I8: The student partially understood the task. | J8: The student could understand and partially explain the task. | K8: The student was quick to understand the task and could explain the same with clarity. | M8: The student could not get a solution within the given time. | N8: The student struggled to get a solution for the first task. | O8: The student got a solution for the first task but struggled a bit with further tasks. | P8: The student could get the solution for most of the tasks easily and also experimented new tasks. | R8: The student showed very little interest in the activity. | S8: The student displayed a fair bit of interest in the activity. | T8: The student participated in the activity with interest. | U8: The student was excited about performing the activity. | W8: The student was a passive member of the team. | X8: The student was considering all the opinions of the team members. | Y8: The student was able to filter and go ahead with the right opinion provided by the teammates | Z8: The student completed his/her work and also helped others team members by solving their difficulties wherever possible.
C9: 2 | D9: 3 | E9: 4 | F9: 5 | G9: Total/5 | H9: 2 | I9: 3 | J9: 4 | K9: 5 | L9: Total/5 | M9: 2 | N9: 3 | O9: 4 | P9: 5 | Q9: Total/5 | R9: 2 | S9: 3 | T9: 4 | U9: 5 | V9: Total/5 | W9: 2 | X9: 3 | Y9: 4 | Z9: 5 | AA9: Total/5 | AB9: Grand Total/25 | AC9: Grade
